Workbook

Sheet Sheet1
A1: HSN | B1: PRODUCT | D1: ITEM DESCRIPTION | E1: Price
A2: CODE | B2: CODE | C2: ASIN
D4: TOYS
A5: 95030020 | B5: 1072400 | C5: =VLOOKUP(B:B,Sheet2!B:E,4,0) -> B00VVQRW2G | D5: STACKING CUBES | E5: R129,99
A6: 95030020 | B6: 1073100 | C6: =VLOOKUP(B:B,Sheet2!B:E,4,0) -> B012SHPYNK | D6: LINK STACK & NEST TOY SET | E6: R299,99
A7: 95030020 | B7: 1074500 | C7: =VLOOKUP(B:B,Sheet2!B:E,4,0) -> B00VVQJNMS | D7: NESTING EGGS | E7: R129,99
A8: 95030020 | B8: 1300900 | C8: =VLOOKUP(B:B,Sheet2!B:E,4,0) -> B07C4TFBHH | D8: MY KALEIDOSCOPE | E8: R299,99
A9: 95030020 | B9: 1403100 | C9: =VLOOKUP(B:B,Sheet2!B:E,4,0) -> B0FLDXHGDM | D9: SHAPE SORTER GEAR BOX (PINK) | E9: R199,99
A10: 95030020 | B10: 1729000 | C10: =VLOOKUP(B:B,Sheet2!B:E,4,0) -> B01MTZ4QL8 | D10: KITCHEN | E10: R399,99
A11: 95030099 | B11: 1729300 | C11: =VLOOKUP(B:B,Sheet2!B:E,4,0) -> B076WSQFQD | D11: BAKERY | E11: R399,99
A12: 95030099 | B12: 1730600 | C12: =VLOOKUP(B:B,Sheet2!B:E,4,0) -> B085WGMYLB | D12: CUPCAKE PARTY | E12: R399,99
A13: 95030099 | B13: 1731200 | C13: =VLOOKUP(B:B,Sheet2!B:E,4,0) -> B0B3JFQX7R | D13: FUN PACK | E13: R149,99
A14: 95030099 | B14: 1731300 | C14: =VLOOKUP(B:B,Sheet2!B:E,4,0) -> B00ET0N3QK | D14: MINI FUN PACK | E14: R129,99
A15: 95030099 | B15: 1731800 | C15: =VLOOKUP(B:B,Sheet2!B:E,4,0) -> B0BZP3DXYM | D15: NOODLE PARTY | E15: R399,99
A16: 95030020 | B16: 2120200 | C16: B078XYC3FF | D16: ICE CREAM TURTLE | E16: R279,99
A17: 95030020 | B17: 2120700 | C17: B01M6XY03U | D17: STACK A BOAT | E17: R249,99
A18: 95030020 | B18: 2120800 | C18: B06XX8BH2G | D18: STACK A CAR | E18: R229,99
A19: 95030020 | B19: 2180700 | C19: B0063BMTTA | D19: LITTLE STARS | E19: R149,99
A20: 95030099 | B20: 2351000 | C20: =VLOOKUP(B:B,Sheet2!B:E,4,0) -> B00XNDVDPC | D20: BOX OF COLOUR | E20: R199,99
A21: 95030020 | B21: 4725800 | C21: =VLOOKUP(B:B,Sheet2!B:E,4,0) -> B0DQ17L8MH | D21: WHO'S IT | E21: R299,99
A22: 95030020 | B22: 4970400 | C22: =VLOOKUP(B:B,Sheet2!B:E,4,0) -> B00ET0MN34 | D22: SNAKES & LADDERS | E22: R149,99
A23: 95030020 | B23: 9002500 | C23: =VLOOKUP(B:B,Sheet2!B:E,4,0) -> B00XRKH9J0 | D23: WORKSHOP | E23: R199,99
A24: 95030020 | B24: 9018600 | C24: =VLOOKUP(B:B,Sheet2!B:E,4,0) -> B07ZD85K3K | D24: SAND ART | E24: R299,99
A25: 95030020 | B25: 9018700 | C25: =VLOOKUP(B:B,Sheet2!B:E,4,0) -> B08ZKFTPR6 | D25: SCRAPBOOK KIT | E25: R299,99
A26: 95030020 | B26: 9019800 | C26: =VLOOKUP(B:B,Sheet2!B:E,4,0) -> B0BZP4QWXB | D26: NAIL DESIGN STUDIO | E26: R349,99
A27: 95030020 | B27: 9020300 | C27: =VLOOKUP(B:B,Sheet2!B:E,4,0) -> B0FLDZ4GHN | D27: DIY WRIST BAND KIT | E27: R249,99
A28: 95030020 | B28: 9020400 | C28: =VLOOKUP(B:B,Sheet2!B:E,4,0) -> B0FLDWBHT3 | D28: DIY CROSS STITCH KIT | E28: R279,99
A29: 95049090 | B29: 9414000 | C29: =VLOOKUP(B:B,Sheet2!B:E,4,0) -> B007WSPD4Q | D29: CHESS | E29: R199,99
A30: 95049090 | B30: 9416100 | C30: =VLOOKUP(B:B,Sheet2!B:E,4,0) -> B07PQ35QM9 | D30: LUDO | E30: R149,99
A31: 95030099 | B31: 9421000 | C31: =VLOOKUP(B:B,Sheet2!B:E,4,0) -> B00ELBBFCQ | D31: WORLD MAP | E31: R179,99
... A34: 95030020 | B34: 9425900 | C34: =VLOOKUP(B:B,Sheet2!B:E,4,0) -> B07NNHG7BJ | D34: SOLAR SYSTEM | E34: R179,99
A35: 95030020 | B35: 9537100 | C35: =VLOOKUP(B:B,Sheet2!B:E,4,0) -> #N/A | D35: FIRE TRUCK – MOLTO | E35: R499,99 | J35: NOT LISTED IN AMAZON
A36: 95030020 | B36: 9537400 | C36: =VLOOKUP(B:B,Sheet2!B:E,4,0) -> #N/A | D36: POLICE TRUCK – MOLTO | E36: R499,99 | J36: NOT LISTED IN AMAZON
A37: 95030020 | B37: 9593300 | C37: =VLOOKUP(B:B,Sheet2!B:E,4,0) -> B00XNCV86W | D37: GIFT SET | E37: R199,99
A38: 95030020 | B38: 9609200 | C38: =VLOOKUP(B:B,Sheet2!B:E,4,0) -> B00ELBA5S6 | D38: GLASS PAINTING | E38: R399,99
A39: 95030020 | B39: 9609300 | C39: =VLOOKUP(B:B,Sheet2!B:E,4,0) -> B00ET0N7D4 | D39: CANVAS ART | E39: R279,99
A40: 95030020 | B40: 9609500 | C40: =VLOOKUP(B:B,Sheet2!B:E,4,0) -> B00ELBA7A2 | D40: FINGER PAINTING | E40: R279,99
A41: 95030020 | B41: 9609800 | C41: =VLOOKUP(B:B,Sheet2!B:E,4,0) -> B00JGPIJEE | D41: POP UP GREETING CARDS | E41: R179,99
A42: 95030020 | B42: 9611000 | C42: =VLOOKUP(B:B,Sheet2!B:E,4,0) -> B0076L2ZIG | D42: OTHELLO | E42: R349,99
A43: 95030020 | B43: 9660600 | C43: =VLOOKUP(B:B,Sheet2!B:E,4,0) -> B00ELBA932 | D43: QUILLING ART | E43: R349,99
...

Sheet Sheet2
A1: ASIN | B1: FSIL CODE | C1: Prod Name | D1: BRAND/CATEGORY | E1: ASIN
A2: B0B3JFQX7R | B2: 1731200 | C2: FUN PACK-1731200 | D2: Fundough | E2: B0B3JFQX7R
A3: B08ZKFTXYJ | B3: 9774600 | C3: STRIKE 4-9774600 | D3: Games - Domestic | E3: B08ZKFTXYJ
A4: B00IKBIKYO | B4: 4968200 | C4: TOPPLE - 2013-4968200 | D4: Games - Domestic | E4: B00IKBIKYO
A5: B00ELBBGOI | B5: 9421100 | C5: P&L INDIA MAP PUZZLE - 2013-9421100 | D5: Play & Learn | E5: B00ELBBGOI
A6: B0076L2ZIG | B6: 9611000 | C6: OTHELLO-9611000 | D6: Games - Domestic | E6: B0076L2ZIG
A7: B00ET0MMM6 | B7: 4500100 | C7: SCOTLAND YARD (2013)-4500100 | D7: Games - Domestic | E7: B00ET0MMM6
A8: B0031QBHMA | B8: 9409000 | C8: DOBBLE-9409000 | D8: Asmodee | E8: B0031QBHMA
A9: B09NKYWRD2 | B9: 4935400 | C9: SEQUENCE GAME-4935400 | D9: Games - Domestic | E9: B09NKYWRD2
A10: B00JGPIJEE | B10: 9609800 | C10: POP UP GREETING CARDS - 2014-9609800 | D10: Handycrafts | E10: B00JGPIJEE
A11: B0063BMTTA | B11: 1400100 | C11: STAR LINKS-1400100 | D11: Giggles | E11: B0063BMTTA
A12: B078XYC3FF | B12: 9644600 | C12: ICE CREAM TURTLE-9644600 | D12: Giggles | E12: B078XYC3FF
A13: B00XNCV86W | B13: 9593300 | C13: FDOUGH GIFT SET 2015-9593300 | D13: Fundough | E13: B00XNCV86W
... A227: B081YZP52P | B227: 6388500 | C227: UNDERWATER STRIKE BATMAN-2023-6388500 | D227: Batman | E227: B081YZP52P
A228: 2914849656 | B228: 7131300 | C228: ASM-DIXIT GAME-7131300 | D228: Asmodee | E228: 2914849656
A229: B00XYB2VS6 | B229: 1728500 | C229: FDOUGH - FUN MAT & DOUGH - 2015-1728500 | D229: Fundough | E229: B00XYB2VS6
A230: B09XHV9FL5 | B230: 9949300 | C230: 3 IN 1 DELUXE PLAYGYM-9949300 | D230: Giggles | E230: B09XHV9FL5
A231: 975277324 | B231: 7131700 | C231: ASM-TICKET TO RIDE-7131700 | D231: Asmodee | E231: 975277324
A232: B0CDC1S5M3 | B232: 1401400 | C232: EVER LINKS-1401400 | D232: Giggles | E232: B0CDC1S5M3
A233: B0F6V76ZCS | B233: 4935900 | C233: TRIOMINOS-4935900 | D233: Games - Domestic | E233: B0F6V76ZCS
A234: B007N0KZ64 | B234: 7189800 | C234: ASM-CATAN JUNIOR-7189800 | D234: Asmodee | E234: B007N0KZ64
A235: B0CDC2YFP1 | B235: 1402000 | C235: STACK A ROCKET-1402000 | D235: Giggles | E235: B0CDC2YFP1
A236: B00JGPIQ1K | B236: 9424100 | C236: P&L PZL SPELLING - 2014-9424100 | D236: Play & Learn | E236: B00JGPIQ1K
A237: B00ELB9OOW | B237: 9421300 | C237: P&L ANIMALS PUZZLE - 2013-9421300 | D237: Play & Learn | E237: B00ELB9OOW
A238: B009ZC6AK8 | B238: 2523200 | C238: BUNNY RATTLE (REF 2012)-2523200 | D238: Giggles | E238: B009ZC6AK8
A239: B0CK4P3C16 | B239: 9694800 | C239: BABYS BEST FRIEND COMBO-9694800 | D239: Giggles | E239: B0CK4P3C16
A240: B07PYXD8NG | B240: 9670400 | C240: HANDICRAFTS DREAM CATCHER-9670400 | D240: Handycrafts | E240: B07PYXD8NG
A241: B07PXSJ4LW | B241: 9938600 | C241: MINI VEHICLES DUMP TRUCK-9938600 | D241: Giggles | E241: B07PXSJ4LW
A242: B0DKP57JY4 | B242: 9555800 | C242: UNICORN 4 IN 1 PUZZLE-9555800 | D242: Play & Learn | E242: B0DKP57JY4
A243: B0CZTK1X7Y | B243: 1732200 | C243: FUNDOUGH LIL ROAD EXPLORER - 2024-1732200 | D243: Fundough | E243: B0CZTK1X7Y
... A445: B00ET0MQFY | B445: 9794100 | C445: BEAD STUDIO - 2013-9794100 | D445: Handycrafts | E445: B00ET0MQFY
A446: B09XBN34RZ | B446: 85992IM | C446: ICKY PICKY-85992IM | D446: Games - Domestic | E446: B09XBN34RZ
A447: B007NYF542 | B447: 857100 | C447: FANTASTIC JEWEL DESIGNER-0857100 | D447: Handycrafts | E447: B007NYF542
A448: B0FLDWBHT3 | B448: 9020400 | C448: Handycrafts Funskool DIY Cross Stitch Kit | D448: Handycrafts | E448: B0FLDWBHT3
A449: B09XJZMP6W | B449: 4725700 | C449: Funskool Games Find Me If You Can is a tricky guessing game for thr 6 year old kids and above | D449: Games - Domestic | E449: B09XJZMP6W
A450: B0B5R9KZ9H | B450: 6386400 | C450: DARK CRUSADER BATMAN-2023-6386400 | D450: Batman | E450: B0B5R9KZ9H
A451: B0D9NDWVH2 | B451: 921962I | C451: COLOR CLASH ATOMIC LAUNCHER & EXTRA AMMO-921962I | D451: Color Clash | E451: B0D9NDWVH2
A452: B08ZKBLLVV | B452: 1731000 | C452: FUNDOUGH MAKE LEARN ACTIVITY KIT-1731000 | D452: Fundough | E452: B08ZKBLLVV
A453: B0BNSWFCPS | B453: 9019600 | C453: BABY SHARK - MASK PARTY-9019600 | D453: Handycrafts | E453: B0BNSWFCPS
A454: B0CZTJLWPX | B454: 1732400 | C454: FUNDOUGH FAIRY WORLD-1732400 | D454: Fundough | E454: B0CZTJLWPX
...
